Workbook

Sheet Dashboard
B2: INDIA CPI INFLATION STUDY — ANALYSIS WORKBOOK
B3: NSO CPI Dataset • 2013–2023 • Rural, Urban, Rural+Urban • 27 Categories
B5: Data Cleaning | C5: Fixed typos, imputed missing values, converted data types
B6: Q1: CPI Basket | C6: Broader category contributions to CPI (May 2023) | D6: Tobacco highest at 9.3%
B7: Q2: YoY Trend | C7: Annual inflation rates 2017–2023 with key drivers | D7: 2019 peak at 7.74%
B8: Q3: Food Prices | C8: 12-month food inflation & biggest category contributor | D8: Spices +30.9 pts biggest driver
B9: Q4: COVID Impact | C9: Pre vs post-lockdown inflation across key categories | D9: Post-COVID index +9.4%
B10: Q5: Oil Prices | C10: Correlation of Brent crude with CPI category changes | D10: Fuel & Light strongest +0.548

Sheet Raw_Data
A1: Sector | B1: Year | C1: Month | D1: Cereals and products | E1: Meat and fish | F1: Egg | G1: Milk and products | H1: Oils and fats | I1: Fruits | J1: Vegetables | K1: Pulses and products | L1: Sugar and Confectionery | M1: Spices | N1: Non-alcoholic beverages | O1: Prepared meals, snacks, sweets etc. | P1: Food and beverages | Q1: Pan, tobacco and intoxicants | R1: Clothing | S1: Footwear | T1: Clothing and footwear | U1: Housing | V1: Fuel and light | W1: Household goods and services | X1: Health | Y1: Transport and communication | Z1: Recreation and amusement | AA1: Education | AB1: Personal care and effects | AC1: Miscellaneous | AD1: General index
A2: Rural | B2: 2013 | C2: January | D2: 107.5 | E2: 106.3 | F2: 108.1 | G2: 104.9 | H2: 106.1 | I2: 103.9 | J2: 101.9 | K2: 106.1 | L2: 106.8 | M2: 103.1 | N2: 104.8 | O2: 106.7 | P2: 105.5 | Q2: 105.1 | R2: 106.5 | S2: 105.8 | T2: 106.4 | U2: NA | V2: 105.5 | W2: 104.8 | X2: 104 | Y2: 103.3 | Z2: 103.4 | AA2: 103.8 | AB2: 104.7 | AC2: 104 | AD2: 105.1
A3: Urban | B3: 2013 | C3: January | D3: 110.5 | E3: 109.1 | F3: 113 | G3: 103.6 | H3: 103.4 | I3: 102.3 | J3: 102.9 | K3: 105.8 | L3: 105.1 | M3: 101.8 | N3: 105.1 | O3: 107.9 | P3: 105.9 | Q3: 105.2 | R3: 105.9 | S3: 105 | T3: 105.8 | U3: 100.3 | V3: 105.4 | W3: 104.8 | X3: 104.1 | Y3: 103.2 | Z3: 102.9 | AA3: 103.5 | AB3: 104.3 | AC3: 103.7 | AD3: 104
A4: Rural+Urban | B4: 2013 | C4: January | D4: 108.4 | E4: 107.3 | F4: 110 | G4: 104.4 | H4: 105.1 | I4: 103.2 | J4: 102.2 | K4: 106 | L4: 106.2 | M4: 102.7 | N4: 104.9 | O4: 107.3 | P4: 105.6 | Q4: 105.1 | R4: 106.3 | S4: 105.5 | T4: 106.2 | U4: 100.3 | V4: 105.5 | W4: 104.8 | X4: 104 | Y4: 103.2 | Z4: 103.1 | AA4: 103.6 | AB4: 104.5 | AC4: 103.9 | AD4: 104.6
A5: Rural | B5: 2013 | C5: February | D5: 109.2 | E5: 108.7 | F5: 110.2 | G5: 105.4 | H5: 106.7 | I5: 104 | J5: 102.4 | K5: 105.9 | L5: 105.7 | M5: 103.1 | N5: 105.1 | O5: 107.7 | P5: 106.3 | Q5: 105.6 | R5: 107.1 | S5: 106.3 | T5: 107 | U5: NA | V5: 106.2 | W5: 105.2 | X5: 104.4 | Y5: 103.9 | Z5: 104 | AA5: 104.1 | AB5: 104.6 | AC5: 104.4 | AD5: 105.8
A6: Urban | B6: 2013 | C6: February | D6: 112.9 | E6: 112.9 | F6: 116.9 | G6: 104 | H6: 103.5 | I6: 103.1 | J6: 104.9 | K6: 104.1 | L6: 103.8 | M6: 102.3 | N6: 106 | O6: 109 | P6: 107.2 | Q6: 106 | R6: 106.6 | S6: 105.5 | T6: 106.4 | U6: 100.4 | V6: 105.7 | W6: 105.2 | X6: 104.7 | Y6: 104.4 | Z6: 103.3 | AA6: 103.7 | AB6: 104.3 | AC6: 104.3 | AD6: 104.7
A7: Rural+Urban | B7: 2013 | C7: February | D7: 110.4 | E7: 110.2 | F7: 112.8 | G7: 104.9 | H7: 105.5 | I7: 103.6 | J7: 103.2 | K7: 105.3 | L7: 105.1 | M7: 102.8 | N7: 105.5 | O7: 108.3 | P7: 106.6 | Q7: 105.7 | R7: 106.9 | S7: 106 | T7: 106.8 | U7: 100.4 | V7: 106 | W7: 105.2 | X7: 104.5 | Y7: 104.2 | Z7: 103.6 | AA7: 103.9 | AB7: 104.5 | AC7: 104.4 | AD7: 105.3
A8: Rural | B8: 2013 | C8: March | D8: 110.2 | E8: 108.8 | F8: 109.9 | G8: 105.6 | H8: 106.2 | I8: 105.7 | J8: 101.4 | K8: 105.7 | L8: 105 | M8: 103.3 | N8: 105.6 | O8: 108.2 | P8: 106.6 | Q8: 106.5 | R8: 107.6 | S8: 106.8 | T8: 107.5 | U8: NA | V8: 106.1 | W8: 105.6 | X8: 104.7 | Y8: 104.6 | Z8: 104 | AA8: 104.3 | AB8: 104.3 | AC8: 104.6 | AD8: 106
A9: Urban | B9: 2013 | C9: March | D9: 113.9 | E9: 111.4 | F9: 113.2 | G9: 104.3 | H9: 102.7 | I9: 104.9 | J9: 103.8 | K9: 103.5 | L9: 102.6 | M9: 102.4 | N9: 107 | O9: 109.8 | P9: 107.3 | Q9: 106.8 | R9: 107.2 | S9: 106 | T9: 107 | U9: 100.4 | V9: 106 | W9: 105.7 | X9: 105.2 | Y9: 105.5 | Z9: 103.5 | AA9: 103.8 | AB9: 104.2 | AC9: 104.9 | AD9: 105
A10: Rural+Urban | B10: 2013 | C10: March | D10: 111.4 | E10: 109.7 | F10: 111.2 | G10: 105.1 | H10: 104.9 | I10: 105.3 | J10: 102.2 | K10: 105 | L10: 104.2 | M10: 103 | N10: 106.2 | O10: 108.9 | P10: 106.9 | Q10: 106.6 | R10: 107.4 | S10: 106.5 | T10: 107.3 | U10: 100.4 | V10: 106.1 | W10: 105.6 | X10: 104.9 | Y10: 105.1 | Z10: 103.7 | AA10: 104 | AB10: 104.3 | AC10: 104.7 | AD10: 105.5
A11: Rural | B11: 2013 | C11: April | D11: 110.2 | E11: 109.5 | F11: 106.9 | G11: 106.3 | H11: 105.7 | I11: 108.3 | J11: 103.4 | K11: 105.7 | L11: 104.2 | M11: 103.2 | N11: 106.5 | O11: 108.8 | P11: 107.1 | Q11: 107.1 | R11: 108.1 | S11: 107.4 | T11: 108 | U11: NA | V11: 106.5 | W11: 106.1 | X11: 105.1 | Y11: 104.4 | Z11: 104.5 | AA11: 104.8 | AB11: 102.7 | AC11: 104.6 | AD11: 106.4
A12: Urban | B12: 2013 | C12: April | D12: 114.6 | E12: 113.4 | F12: 106 | G12: 104.7 | H12: 102.1 | I12: 109.5 | J12: 109.7 | K12: 104.6 | L12: 102 | M12: 103.5 | N12: 108.2 | O12: 110.6 | P12: 108.8 | Q12: 108.5 | R12: 107.9 | S12: 106.4 | T12: 107.7 | U12: 100.5 | V12: 106.4 | W12: 106.5 | X12: 105.7 | Y12: 105 | Z12: 104 | AA12: 105.2 | AB12: 103.2 | AC12: 105.1 | AD12: 105.7
A13: Rural+Urban | B13: 2013 | C13: April | D13: 111.6 | E13: 110.9 | F13: 106.6 | G13: 105.7 | H13: 104.4 | I13: 108.9 | J13: 105.5 | K13: 105.3 | L13: 103.5 | M13: 103.3 | N13: 107.2 | O13: 109.6 | P13: 107.7 | Q13: 107.5 | R13: 108 | S13: 107 | T13: 107.9 | U13: 100.5 | V13: 106.5 | W13: 106.3 | X13: 105.3 | Y13: 104.7 | Z13: 104.2 | AA13: 105 | AB13: 102.9 | AC13: 104.8 | AD13: 106.1
A14: Rural | B14: 2013 | C14: May | D14: 110.9 | E14: 109.8 | F14: 105.9 | G14: 107.5 | H14: 105.3 | I14: 108.1 | J14: 107.3 | K14: 106.1 | L14: 103.7 | M14: 104 | N14: 107.4 | O14: 109.9 | P14: 108.1 | Q14: 108.1 | R14: 108.8 | S14: 107.9 | T14: 108.6 | U14: NA | V14: 107.5 | W14: 106.8 | X14: 105.7 | Y14: 104.1 | Z14: 105 | AA14: 105.5 | AB14: 102.1 | AC14: 104.8 | AD14: 107.2
A15: Urban | B15: 2013 | C15: May | D15: 115.4 | E15: 114.2 | F15: 102.7 | G15: 105.5 | H15: 101.5 | I15: 110.6 | J15: 123.7 | K15: 105.2 | L15: 101.9 | M15: 105 | N15: 109.1 | O15: 111.3 | P15: 111.1 | Q15: 109.8 | R15: 108.5 | S15: 106.7 | T15: 108.3 | U15: 100.5 | V15: 107.2 | W15: 107.1 | X15: 106.2 | Y15: 103.9 | Z15: 104.6 | AA15: 105.7 | AB15: 102.6 | AC15: 104.9 | AD15: 106.6
A16: Rural+Urban | B16: 2013 | C16: May | D16: 112.3 | E16: 111.3 | F16: 104.7 | G16: 106.8 | H16: 103.9 | I16: 109.3 | J16: 112.9 | K16: 105.8 | L16: 103.1 | M16: 104.3 | N16: 108.1 | O16: 110.5 | P16: 109.2 | Q16: 108.6 | R16: 108.7 | S16: 107.4 | T16: 108.5 | U16: 100.5 | V16: 107.4 | W16: 106.9 | X16: 105.9 | Y16: 104 | Z16: 104.8 | AA16: 105.6 | AB16: 102.3 | AC16: 104.8 | AD16: 106.9
A17: Rural | B17: 2013 | C17: June | D17: 112.3 | E17: 112.1 | F17: 108.1 | G17: 108.3 | H17: 105.9 | I17: 109.2 | J17: 118 | K17: 106.8 | L17: 104.1 | M17: 105.4 | N17: 108.2 | O17: 111 | P17: 110.6 | Q17: 109 | R17: 109.7 | S17: 108.8 | T17: 109.5 | U17: NA | V17: 108.5 | W17: 107.5 | X17: 106.3 | Y17: 105 | Z17: 105.6 | AA17: 106.5 | AB17: 102.5 | AC17: 105.5 | AD17: 108.9
A18: Urban | B18: 2013 | C18: June | D18: 117 | E18: 120.1 | F18: 112.5 | G18: 107.3 | H18: 101.3 | I18: 112.4 | J18: 143.6 | K18: 105.4 | L18: 101.4 | M18: 106.4 | N18: 110 | O18: 112.2 | P18: 115 | Q18: 110.9 | R18: 109.2 | S18: 107.2 | T18: 108.9 | U18: 106.6 | V18: 108 | W18: 107.7 | X18: 106.5 | Y18: 105.2 | Z18: 105.2 | AA18: 108.1 | AB18: 103.3 | AC18: 106.1 | AD18: 109.7
A19: Rural+Urban | B19: 2013 | C19: June | D19: 113.8 | E19: 114.9 | F19: 109.8 | G19: 107.9 | H19: 104.2 | I19: 110.7 | J19: 126.7 | K19: 106.3 | L19: 103.2 | M19: 105.7 | N19: 109 | O19: 111.6 | P19: 112.2 | Q19: 109.5 | R19: 109.5 | S19: 108.1 | T19: 109.3 | U19: 106.6 | V19: 108.3 | W19: 107.6 | X19: 106.4 | Y19: 105.1 | Z19: 105.4 | AA19: 107.4 | AB19: 102.8 | AC19: 105.8 | AD19: 109.3
A20: Rural | B20: 2013 | C20: July | D20: 113.4 | E20: 114.9 | F20: 110.5 | G20: 109.3 | H20: 106.2 | I20: 110.3 | J20: 129.2 | K20: 107.1 | L20: 104.3 | M20: 106.4 | N20: 109.1 | O20: 112.1 | P20: 113.1 | Q20: 109.8 | R20: 110.5 | S20: 109.5 | T20: 110.3 | U20: NA | V20: 109.5 | W20: 108.3 | X20: 106.9 | Y20: 106.8 | Z20: 106.4 | AA20: 107.8 | AB20: 102.5 | AC20: 106.5 | AD20: 110.7
A21: Urban | B21: 2013 | C21: July | D21: 117.8 | E21: 119.2 | F21: 114 | G21: 108.3 | H21: 101.1 | I21: 113.2 | J21: 160.9 | K21: 105.1 | L21: 101.3 | M21: 107.5 | N21: 110.4 | O21: 113.1 | P21: 117.5 | Q21: 111.7 | R21: 109.8 | S21: 107.8 | T21: 109.5 | U21: 107.7 | V21: 108.6 | W21: 108.1 | X21: 107.1 | Y21: 107.3 | Z21: 105.9 | AA21: 110.1 | AB21: 103.2 | AC21: 107.3 | AD21: 111.4
A22: Rural+Urban | B22: 2013 | C22: July | D22: 114.8 | E22: 116.4 | F22: 111.9 | G22: 108.9 | H22: 104.3 | I22: 111.7 | J22: 140 | K22: 106.4 | L22: 103.3 | M22: 106.8 | N22: 109.6 | O22: 112.6 | P22: 114.7 | Q22: 110.3 | R22: 110.2 | S22: 108.8 | T22: 110 | U22: 107.7 | V22: 109.2 | W22: 108.2 | X22: 107 | Y22: 107.1 | Z22: 106.1 | AA22: 109.1 | AB22: 102.8 | AC22: 106.9 | AD22: 111
A23: Rural | B23: 2013 | C23: August | D23: 114.3 | E23: 115.4 | F23: 111.1 | G23: 110 | H23: 106.4 | I23: 110.8 | J23: 138.9 | K23: 107.4 | L23: 104.1 | M23: 106.9 | N23: 109.7 | O23: 112.6 | P23: 114.9 | Q23: 110.7 | R23: 111.3 | S23: 110.2 | T23: 111.1 | U23: NA | V23: 109.9 | W23: 108.7 | X23: 107.5 | Y23: 107.8 | Z23: 106.8 | AA23: 108.7 | AB23: 105 | AC23: 107.5 | AD23: 112.1
A24: Urban | B24: 2013 | C24: August | D24: 118.3 | E24: 120.4 | F24: 112.7 | G24: 108.9 | H24: 101.1 | I24: 108.7 | J24: 177 | K24: 104.7 | L24: 101 | M24: 108.5 | N24: 110.9 | O24: 114.3 | P24: 119.6 | Q24: 112.4 | R24: 110.6 | S24: 108.3 | T24: 110.2 | U24: 108.9 | V24: 109.3 | W24: 108.7 | X24: 107.6 | Y24: 108.1 | Z24: 106.5 | AA24: 110.8 | AB24: 106 | AC24: 108.3 | AD24: 112.7
A25: Rural+Urban | B25: 2013 | C25: August | D25: 115.6 | E25: 117.2 | F25: 111.7 | G25: 109.6 | H25: 104.5 | I25: 109.8 | J25: 151.8 | K25: 106.5 | L25: 103.1 | M25: 107.4 | N25: 110.2 | O25: 113.4 | P25: 116.6 | Q25: 111.2 | R25: 111 | S25: 109.4 | T25: 110.7 | U25: 108.9 | V25: 109.7 | W25: 108.7 | X25: 107.5 | Y25: 108 | Z25: 106.6 | AA25: 109.9 | AB25: 105.4 | AC25: 107.9 | AD25: 112.4
A26: Rural | B26: 2013 | C26: September | D26: 115.4 | E26: 115.7 | F26: 111.7 | G26: 111 | H26: 107.4 | I26: 110.9 | J26: 154 | K26: 108.1 | L26: 104.2 | M26: 107.9 | N26: 110.4 | O26: 114 | P26: 117.8 | Q26: 111.7 | R26: 112.7 | S26: 111.4 | T26: 112.5 | U26: NA | V26: 111.1 | W26: 109.6 | X26: 108.3 | Y26: 109.3 | Z26: 107.7 | AA26: 109.8 | AB26: 106.7 | AC26: 108.7 | AD26: 114.2
A27: Urban | B27: 2013 | C27: September | D27: 118.6 | E27: 119.1 | F27: 113.2 | G27: 109.6 | H27: 101.7 | I27: 103.2 | J27: 174.3 | K27: 105.1 | L27: 100.8 | M27: 109.1 | N27: 111.1 | O27: 115.4 | P27: 119.2 | Q27: 112.9 | R27: 111.4 | S27: 109 | T27: 111.1 | U27: 109.7 | V27: 109.5 | W27: 109.6 | X27: 107.9 | Y27: 110.4 | Z27: 107.4 | AA27: 111.2 | AB27: 106.9 | AC27: 109.4 | AD27: 113.2
A28: Rural+Urban | B28: 2013 | C28: September | D28: 116.4 | E28: 116.9 | F28: 112.3 | G28: 110.5 | H28: 105.3 | I28: 107.3 | J28: 160.9 | K28: 107.1 | L28: 103.1 | M28: 108.3 | N28: 110.7 | O28: 114.6 | P28: 118.3 | Q28: 112 | R28: 112.2 | S28: 110.4 | T28: 111.9 | U28: 109.7 | V28: 110.5 | W28: 109.6 | X28: 108.1 | Y28: 109.9 | Z28: 107.5 | AA28: 110.6 | AB28: 106.8 | AC28: 109 | AD28: 113.7
A29: Rural | B29: 2013 | C29: October | D29: 116.3 | E29: 115.4 | F29: 112.6 | G29: 111.7 | H29: 107.7 | I29: 113.2 | J29: 164.9 | K29: 108.3 | L29: 103.9 | M29: 108.2 | N29: 111.1 | O29: 114.9 | P29: 119.8 | Q29: 112.2 | R29: 113.6 | S29: 112.3 | T29: 113.4 | U29: NA | V29: 111.6 | W29: 110.4 | X29: 108.9 | Y29: 109.3 | Z29: 108.3 | AA29: 110.2 | AB29: 107.5 | AC29: 109.1 | AD29: 115.5
A30: Urban | B30: 2013 | C30: October | D30: 118.9 | E30: 118.1 | F30: 114.5 | G30: 110.4 | H30: 102.3 | I30: 106.2 | J30: 183.5 | K30: 105.3 | L30: 100.2 | M30: 109.6 | N30: 111.4 | O30: 116 | P30: 120.8 | Q30: 113.5 | R30: 112.5 | S30: 109.7 | T30: 112 | U30: 110.5 | V30: 109.7 | W30: 110.2 | X30: 108.2 | Y30: 109.7 | Z30: 108 | AA30: 111.3 | AB30: 107.3 | AC30: 109.4 | AD30: 114
A31: Rural+Urban | B31: 2013 | C31: October | D31: 117.1 | E31: 116.3 | F31: 113.3 | G31: 111.2 | H31: 105.7 | I31: 109.9 | J31: 171.2 | K31: 107.3 | L31: 102.7 | M31: 108.7 | N31: 111.2 | O31: 115.4 | P31: 120.2 | Q31: 112.5 | R31: 113.2 | S31: 111.2 | T31: 112.8 | U31: 110.5 | V31: 110.9 | W31: 110.3 | X31: 108.6 | Y31: 109.5 | Z31: 108.1 | AA31: 110.8 | AB31: 107.4 | AC31: 109.2 | AD31: 114.8
A32: Rural | B32: 2013 | C32: November | D32: 117.3 | E32: 114.9 | F32: 116.2 | G32: 112.8 | H32: 108.9 | I32: 116.6 | J32: 178.1 | K32: 109.1 | L32: 103.6 | M32: 109 | N32: 111.8 | O32: 116 | P32: 122.5 | Q32: 112.8 | R32: 114.6 | S32: 113.1 | T32: 114.4 | U32: NA | V32: 112.6 | W32: 111.3 | X32: 109.7 | Y32: 109.6 | Z32: 108.7 | AA32: 111 | AB32: 108.2 | AC32: 109.8 | AD32: 117.4
A33: Urban | B33: 2013 | C33: November | D33: 119.8 | E33: 116.3 | F33: 122.6 | G33: 112 | H33: 103.2 | I33: 110 | J33: 192.8 | K33: 106.3 | L33: 99.5 | M33: 110.3 | N33: 111.8 | O33: 117.1 | P33: 122.9 | Q33: 114.1 | R33: 113.5 | S33: 110.3 | T33: 113 | U33: 111.1 | V33: 110 | W33: 110.9 | X33: 108.6 | Y33: 109.5 | Z33: 108.5 | AA33: 111.3 | AB33: 107.9 | AC33: 109.6 | AD33: 115
A34: Rural+Urban | B34: 2013 | C34: November | D34: 118.1 | E34: 115.4 | F34: 118.7 | G34: 112.5 | H34: 106.8 | I34: 113.5 | J34: 183.1 | K34: 108.2 | L34: 102.2 | M34: 109.4 | N34: 111.8 | O34: 116.5 | P34: 122.6 | Q34: 113.1 | R34: 114.2 | S34: 111.9 | T34: 113.8 | U34: 111.1 | V34: 111.6 | W34: 111.1 | X34: 109.3 | Y34: 109.5 | Z34: 108.6 | AA34: 111.2 | AB34: 108.1 | AC34: 109.7 | AD34: 116.3
A35: Rural | B35: 2013 | C35: December | D35: 118.4 | E35: 115.9 | F35: 120.4 | G35: 113.8 | H35: 109.5 | I35: 115.5 | J35: 145.7 | K35: 109.5 | L35: 102.9 | M35: 109.8 | N35: 112.1 | O35: 116.8 | P35: 118.7 | Q35: 113.6 | R35: 115.8 | S35: 114 | T35: 115.5 | U35: NA | V35: 112.8 | W35: 112.1 | X35: 110.1 | Y35: 109.9 | Z35: 109.2 | AA35: 111.6 | AB35: 108.1 | AC35: 110.1 | AD35: 115.5
A36: Urban | B36: 2013 | C36: December | D36: 120.5 | E36: 118.1 | F36: 128.5 | G36: 112.8 | H36: 103.4 | I36: 110.7 | J36: 144.8 | K36: 107.1 | L36: 98.6 | M36: 111.9 | N36: 112.1 | O36: 118.1 | P36: 117.8 | Q36: 115 | R36: 114.2 | S36: 110.9 | T36: 113.7 | U36: 110.7 | V36: 110.4 | W36: 111.3 | X36: 109 | Y36: 109.7 | Z36: 108.9 | AA36: 111.4 | AB36: 107.7 | AC36: 109.8 | AD36: 113.3
A37: Rural+Urban | B37: 2013 | C37: December | D37: 119.1 | E37: 116.7 | F37: 123.5 | G37: 113.4 | H37: 107.3 | I37: 113.3 | J37: 145.4 | K37: 108.7 | L37: 101.5 | M37: 110.5 | N37: 112.1 | O37: 117.4 | P37: 118.4 | Q37: 114 | R37: 115.2 | S37: 112.7 | T37: 114.8 | U37: 110.7 | V37: 111.9 | W37: 111.7 | X37: 109.7 | Y37: 109.8 | Z37: 109 | AA37: 111.5 | AB37: 107.9 | AC37: 110 | AD37: 114.5
A38: Rural | B38: 2014 | C38: January | D38: 118.9 | E38: 117.1 | F38: 120.5 | G38: 114.4 | H38: 109 | I38: 115.5 | J38: 123.9 | K38: 109.6 | L38: 101.8 | M38: 110.2 | N38: 112.4 | O38: 117.3 | P38: 116 | Q38: 114 | R38: 116.5 | S38: 114.5 | T38: 116.2 | U38: NA | V38: 113 | W38: 112.6 | X38: 110.6 | Y38: 110.5 | Z38: 109.6 | AA38: 111.8 | AB38: 108.3 | AC38: 110.6 | AD38: 114.2
A39: Urban | B39: 2014 | C39: January | D39: 121.2 | E39: 122 | F39: 129.9 | G39: 113.6 | H39: 102.9 | I39: 112.1 | J39: 118.9 | K39: 107.5 | L39: 96.9 | M39: 112.7 | N39: 112.1 | O39: 119 | P39: 115.5 | Q39: 115.7 | R39: 114.8 | S39: 111.3 | T39: 114.3 | U39: 111.6 | V39: 111 | W39: 111.9 | X39: 109.7 | Y39: 110.8 | Z39: 109.8 | AA39: 111.5 | AB39: 108 | AC39: 110.5 | AD39: 112.9
A40: Rural+Urban | B40: 2014 | C40: January | D40: 119.6 | E40: 118.8 | F40: 124.1 | G40: 114.1 | H40: 106.8 | I40: 113.9 | J40: 122.2 | K40: 108.9 | L40: 100.2 | M40: 111 | N40: 112.3 | O40: 118.1 | P40: 115.8 | Q40: 114.5 | R40: 115.8 | S40: 113.2 | T40: 115.4 | U40: 111.6 | V40: 112.2 | W40: 112.3 | X40: 110.3 | Y40: 110.7 | Z40: 109.7 | AA40: 111.6 | AB40: 108.2 | AC40: 110.6 | AD40: 113.6
...

Sheet Clean_Data
A1: Sector | B1: Year | C1: Month | D1: Cereals and products | E1: Meat and fish | F1: Egg | G1: Milk and products | H1: Oils and fats | I1: Fruits | J1: Vegetables | K1: Pulses and products | L1: Sugar and Confectionery | M1: Spices | N1: Non alcoholic beverages | O1: Prepared meals, snacks, sweets etc. | P1: Food and beverages | Q1: Pan, tobacco and intoxicants | R1: Clothing | S1: Footwear | T1: Clothing and footwear | U1: Housing | V1: Fuel and light | W1: Household goods and services | X1: Health | Y1: Transport and communication | Z1: Recreation and amusement | AA1: Education | AB1: Personal care and effects | AC1: Miscellaneous | AD1: General index
A2: Rural | B2: 2013 | C2: January | D2: 107.5 | E2: 106.3 | F2: 108.1 | G2: 104.9 | H2: 106.1 | I2: 103.9 | J2: 101.9 | K2: 106.1 | L2: 106.8 | M2: 103.1 | N2: 104.8 | O2: 106.7 | P2: 105.5 | Q2: 105.1 | R2: 106.5 | S2: 105.8 | T2: 106.4 | U2: NA | V2: 105.5 | W2: 104.8 | X2: 104 | Y2: 103.3 | Z2: 103.4 | AA2: 103.8 | AB2: 104.7 | AC2: 104 | AD2: 105.1
A3: Urban | B3: 2013 | C3: January | D3: 110.5 | E3: 109.1 | F3: 113 | G3: 103.6 | H3: 103.4 | I3: 102.3 | J3: 102.9 | K3: 105.8 | L3: 105.1 | M3: 101.8 | N3: 105.1 | O3: 107.9 | P3: 105.9 | Q3: 105.2 | R3: 105.9 | S3: 105 | T3: 105.8 | U3: 100.3 | V3: 105.4 | W3: 104.8 | X3: 104.1 | Y3: 103.2 | Z3: 102.9 | AA3: 103.5 | AB3: 104.3 | AC3: 103.7 | AD3: 104
A4: Rural+Urban | B4: 2013 | C4: January | D4: 108.4 | E4: 107.3 | F4: 110 | G4: 104.4 | H4: 105.1 | I4: 103.2 | J4: 102.2 | K4: 106 | L4: 106.2 | M4: 102.7 | N4: 104.9 | O4: 107.3 | P4: 105.6 | Q4: 105.1 | R4: 106.3 | S4: 105.5 | T4: 106.2 | U4: 100.3 | V4: 105.5 | W4: 104.8 | X4: 104 | Y4: 103.2 | Z4: 103.1 | AA4: 103.6 | AB4: 104.5 | AC4: 103.9 | AD4: 104.6
A5: Rural | B5: 2013 | C5: February | D5: 109.2 | E5: 108.7 | F5: 110.2 | G5: 105.4 | H5: 106.7 | I5: 104 | J5: 102.4 | K5: 105.9 | L5: 105.7 | M5: 103.1 | N5: 105.1 | O5: 107.7 | P5: 106.3 | Q5: 105.6 | R5: 107.1 | S5: 106.3 | T5: 107 | U5: NA | V5: 106.2 | W5: 105.2 | X5: 104.4 | Y5: 103.9 | Z5: 104 | AA5: 104.1 | AB5: 104.6 | AC5: 104.4 | AD5: 105.8
A6: Urban | B6: 2013 | C6: February | D6: 112.9 | E6: 112.9 | F6: 116.9 | G6: 104 | H6: 103.5 | I6: 103.1 | J6: 104.9 | K6: 104.1 | L6: 103.8 | M6: 102.3 | N6: 106 | O6: 109 | P6: 107.2 | Q6: 106 | R6: 106.6 | S6: 105.5 | T6: 106.4 | U6: 100.4 | V6: 105.7 | W6: 105.2 | X6: 104.7 | Y6: 104.4 | Z6: 103.3 | AA6: 103.7 | AB6: 104.3 | AC6: 104.3 | AD6: 104.7
A7: Rural+Urban | B7: 2013 | C7: February | D7: 110.4 | E7: 110.2 | F7: 112.8 | G7: 104.9 | H7: 105.5 | I7: 103.6 | J7: 103.2 | K7: 105.3 | L7: 105.1 | M7: 102.8 | N7: 105.5 | O7: 108.3 | P7: 106.6 | Q7: 105.7 | R7: 106.9 | S7: 106 | T7: 106.8 | U7: 100.4 | V7: 106 | W7: 105.2 | X7: 104.5 | Y7: 104.2 | Z7: 103.6 | AA7: 103.9 | AB7: 104.5 | AC7: 104.4 | AD7: 105.3
A8: Rural | B8: 2013 | C8: March | D8: 110.2 | E8: 108.8 | F8: 109.9 | G8: 105.6 | H8: 106.2 | I8: 105.7 | J8: 101.4 | K8: 105.7 | L8: 105 | M8: 103.3 | N8: 105.6 | O8: 108.2 | P8: 106.6 | Q8: 106.5 | R8: 107.6 | S8: 106.8 | T8: 107.5 | U8: NA | V8: 106.1 | W8: 105.6 | X8: 104.7 | Y8: 104.6 | Z8: 104 | AA8: 104.3 | AB8: 104.3 | AC8: 104.6 | AD8: 106
A9: Urban | B9: 2013 | C9: March | D9: 113.9 | E9: 111.4 | F9: 113.2 | G9: 104.3 | H9: 102.7 | I9: 104.9 | J9: 103.8 | K9: 103.5 | L9: 102.6 | M9: 102.4 | N9: 107 | O9: 109.8 | P9: 107.3 | Q9: 106.8 | R9: 107.2 | S9: 106 | T9: 107 | U9: 100.4 | V9: 106 | W9: 105.7 | X9: 105.2 | Y9: 105.5 | Z9: 103.5 | AA9: 103.8 | AB9: 104.2 | AC9: 104.9 | AD9: 105
A10: Rural+Urban | B10: 2013 | C10: March | D10: 111.4 | E10: 109.7 | F10: 111.2 | G10: 105.1 | H10: 104.9 | I10: 105.3 | J10: 102.2 | K10: 105 | L10: 104.2 | M10: 103 | N10: 106.2 | O10: 108.9 | P10: 106.9 | Q10: 106.6 | R10: 107.4 | S10: 106.5 | T10: 107.3 | U10: 100.4 | V10: 106.1 | W10: 105.6 | X10: 104.9 | Y10: 105.1 | Z10: 103.7 | AA10: 104 | AB10: 104.3 | AC10: 104.7 | AD10: 105.5
A11: Rural | B11: 2013 | C11: April | D11: 110.2 | E11: 109.5 | F11: 106.9 | G11: 106.3 | H11: 105.7 | I11: 108.3 | J11: 103.4 | K11: 105.7 | L11: 104.2 | M11: 103.2 | N11: 106.5 | O11: 108.8 | P11: 107.1 | Q11: 107.1 | R11: 108.1 | S11: 107.4 | T11: 108 | U11: NA | V11: 106.5 | W11: 106.1 | X11: 105.1 | Y11: 104.4 | Z11: 104.5 | AA11: 104.8 | AB11: 102.7 | AC11: 104.6 | AD11: 106.4
A12: Urban | B12: 2013 | C12: April | D12: 114.6 | E12: 113.4 | F12: 106 | G12: 104.7 | H12: 102.1 | I12: 109.5 | J12: 109.7 | K12: 104.6 | L12: 102 | M12: 103.5 | N12: 108.2 | O12: 110.6 | P12: 108.8 | Q12: 108.5 | R12: 107.9 | S12: 106.4 | T12: 107.7 | U12: 100.5 | V12: 106.4 | W12: 106.5 | X12: 105.7 | Y12: 105 | Z12: 104 | AA12: 105.2 | AB12: 103.2 | AC12: 105.1 | AD12: 105.7
A13: Rural+Urban | B13: 2013 | C13: April | D13: 111.6 | E13: 110.9 | F13: 106.6 | G13: 105.7 | H13: 104.4 | I13: 108.9 | J13: 105.5 | K13: 105.3 | L13: 103.5 | M13: 103.3 | N13: 107.2 | O13: 109.6 | P13: 107.7 | Q13: 107.5 | R13: 108 | S13: 107 | T13: 107.9 | U13: 100.5 | V13: 106.5 | W13: 106.3 | X13: 105.3 | Y13: 104.7 | Z13: 104.2 | AA13: 105 | AB13: 102.9 | AC13: 104.8 | AD13: 106.1
A14: Rural | B14: 2013 | C14: May | D14: 110.9 | E14: 109.8 | F14: 105.9 | G14: 107.5 | H14: 105.3 | I14: 108.1 | J14: 107.3 | K14: 106.1 | L14: 103.7 | M14: 104 | N14: 107.4 | O14: 109.9 | P14: 108.1 | Q14: 108.1 | R14: 108.8 | S14: 107.9 | T14: 108.6 | U14: NA | V14: 107.5 | W14: 106.8 | X14: 105.7 | Y14: 104.1 | Z14: 105 | AA14: 105.5 | AB14: 102.1 | AC14: 104.8 | AD14: 107.2
A15: Urban | B15: 2013 | C15: May | D15: 115.4 | E15: 114.2 | F15: 102.7 | G15: 105.5 | H15: 101.5 | I15: 110.6 | J15: 123.7 | K15: 105.2 | L15: 101.9 | M15: 105 | N15: 109.1 | O15: 111.3 | P15: 111.1 | Q15: 109.8 | R15: 108.5 | S15: 106.7 | T15: 108.3 | U15: 100.5 | V15: 107.2 | W15: 107.1 | X15: 106.2 | Y15: 103.9 | Z15: 104.6 | AA15: 105.7 | AB15: 102.6 | AC15: 104.9 | AD15: 106.6
A16: Rural+Urban | B16: 2013 | C16: May | D16: 112.3 | E16: 111.3 | F16: 104.7 | G16: 106.8 | H16: 103.9 | I16: 109.3 | J16: 112.9 | K16: 105.8 | L16: 103.1 | M16: 104.3 | N16: 108.1 | O16: 110.5 | P16: 109.2 | Q16: 108.6 | R16: 108.7 | S16: 107.4 | T16: 108.5 | U16: 100.5 | V16: 107.4 | W16: 106.9 | X16: 105.9 | Y16: 104 | Z16: 104.8 | AA16: 105.6 | AB16: 102.3 | AC16: 104.8 | AD16: 106.9
A17: Rural | B17: 2013 | C17: June | D17: 112.3 | E17: 112.1 | F17: 108.1 | G17: 108.3 | H17: 105.9 | I17: 109.2 | J17: 118 | K17: 106.8 | L17: 104.1 | M17: 105.4 | N17: 108.2 | O17: 111 | P17: 110.6 | Q17: 109 | R17: 109.7 | S17: 108.8 | T17: 109.5 | U17: NA | V17: 108.5 | W17: 107.5 | X17: 106.3 | Y17: 105 | Z17: 105.6 | AA17: 106.5 | AB17: 102.5 | AC17: 105.5 | AD17: 108.9
A18: Urban | B18: 2013 | C18: June | D18: 117 | E18: 120.1 | F18: 112.5 | G18: 107.3 | H18: 101.3 | I18: 112.4 | J18: 143.6 | K18: 105.4 | L18: 101.4 | M18: 106.4 | N18: 110 | O18: 112.2 | P18: 115 | Q18: 110.9 | R18: 109.2 | S18: 107.2 | T18: 108.9 | U18: 106.6 | V18: 108 | W18: 107.7 | X18: 106.5 | Y18: 105.2 | Z18: 105.2 | AA18: 108.1 | AB18: 103.3 | AC18: 106.1 | AD18: 109.7
A19: Rural+Urban | B19: 2013 | C19: June | D19: 113.8 | E19: 114.9 | F19: 109.8 | G19: 107.9 | H19: 104.2 | I19: 110.7 | J19: 126.7 | K19: 106.3 | L19: 103.2 | M19: 105.7 | N19: 109 | O19: 111.6 | P19: 112.2 | Q19: 109.5 | R19: 109.5 | S19: 108.1 | T19: 109.3 | U19: 106.6 | V19: 108.3 | W19: 107.6 | X19: 106.4 | Y19: 105.1 | Z19: 105.4 | AA19: 107.4 | AB19: 102.8 | AC19: 105.8 | AD19: 109.3
A20: Rural | B20: 2013 | C20: July | D20: 113.4 | E20: 114.9 | F20: 110.5 | G20: 109.3 | H20: 106.2 | I20: 110.3 | J20: 129.2 | K20: 107.1 | L20: 104.3 | M20: 106.4 | N20: 109.1 | O20: 112.1 | P20: 113.1 | Q20: 109.8 | R20: 110.5 | S20: 109.5 | T20: 110.3 | U20: NA | V20: 109.5 | W20: 108.3 | X20: 106.9 | Y20: 106.8 | Z20: 106.4 | AA20: 107.8 | AB20: 102.5 | AC20: 106.5 | AD20: 110.7
A21: Urban | B21: 2013 | C21: July | D21: 117.8 | E21: 119.2 | F21: 114 | G21: 108.3 | H21: 101.1 | I21: 113.2 | J21: 160.9 | K21: 105.1 | L21: 101.3 | M21: 107.5 | N21: 110.4 | O21: 113.1 | P21: 117.5 | Q21: 111.7 | R21: 109.8 | S21: 107.8 | T21: 109.5 | U21: 107.7 | V21: 108.6 | W21: 108.1 | X21: 107.1 | Y21: 107.3 | Z21: 105.9 | AA21: 110.1 | AB21: 103.2 | AC21: 107.3 | AD21: 111.4
A22: Rural+Urban | B22: 2013 | C22: July | D22: 114.8 | E22: 116.4 | F22: 111.9 | G22: 108.9 | H22: 104.3 | I22: 111.7 | J22: 140 | K22: 106.4 | L22: 103.3 | M22: 106.8 | N22: 109.6 | O22: 112.6 | P22: 114.7 | Q22: 110.3 | R22: 110.2 | S22: 108.8 | T22: 110 | U22: 107.7 | V22: 109.2 | W22: 108.2 | X22: 107 | Y22: 107.1 | Z22: 106.1 | AA22: 109.1 | AB22: 102.8 | AC22: 106.9 | AD22: 111
A23: Rural | B23: 2013 | C23: August | D23: 114.3 | E23: 115.4 | F23: 111.1 | G23: 110 | H23: 106.4 | I23: 110.8 | J23: 138.9 | K23: 107.4 | L23: 104.1 | M23: 106.9 | N23: 109.7 | O23: 112.6 | P23: 114.9 | Q23: 110.7 | R23: 111.3 | S23: 110.2 | T23: 111.1 | U23: NA | V23: 109.9 | W23: 108.7 | X23: 107.5 | Y23: 107.8 | Z23: 106.8 | AA23: 108.7 | AB23: 105 | AC23: 107.5 | AD23: 112.1
A24: Urban | B24: 2013 | C24: August | D24: 118.3 | E24: 120.4 | F24: 112.7 | G24: 108.9 | H24: 101.1 | I24: 108.7 | J24: 177 | K24: 104.7 | L24: 101 | M24: 108.5 | N24: 110.9 | O24: 114.3 | P24: 119.6 | Q24: 112.4 | R24: 110.6 | S24: 108.3 | T24: 110.2 | U24: 108.9 | V24: 109.3 | W24: 108.7 | X24: 107.6 | Y24: 108.1 | Z24: 106.5 | AA24: 110.8 | AB24: 106 | AC24: 108.3 | AD24: 112.7
A25: Rural+Urban | B25: 2013 | C25: August | D25: 115.6 | E25: 117.2 | F25: 111.7 | G25: 109.6 | H25: 104.5 | I25: 109.8 | J25: 151.8 | K25: 106.5 | L25: 103.1 | M25: 107.4 | N25: 110.2 | O25: 113.4 | P25: 116.6 | Q25: 111.2 | R25: 111 | S25: 109.4 | T25: 110.7 | U25: 108.9 | V25: 109.7 | W25: 108.7 | X25: 107.5 | Y25: 108 | Z25: 106.6 | AA25: 109.9 | AB25: 105.4 | AC25: 107.9 | AD25: 112.4
A26: Rural | B26: 2013 | C26: September | D26: 115.4 | E26: 115.7 | F26: 111.7 | G26: 111 | H26: 107.4 | I26: 110.9 | J26: 154 | K26: 108.1 | L26: 104.2 | M26: 107.9 | N26: 110.4 | O26: 114 | P26: 117.8 | Q26: 111.7 | R26: 112.7 | S26: 111.4 | T26: 112.5 | U26: NA | V26: 111.1 | W26: 109.6 | X26: 108.3 | Y26: 109.3 | Z26: 107.7 | AA26: 109.8 | AB26: 106.7 | AC26: 108.7 | AD26: 114.2
A27: Urban | B27: 2013 | C27: September | D27: 118.6 | E27: 119.1 | F27: 113.2 | G27: 109.6 | H27: 101.7 | I27: 103.2 | J27: 174.3 | K27: 105.1 | L27: 100.8 | M27: 109.1 | N27: 111.1 | O27: 115.4 | P27: 119.2 | Q27: 112.9 | R27: 111.4 | S27: 109 | T27: 111.1 | U27: 109.7 | V27: 109.5 | W27: 109.6 | X27: 107.9 | Y27: 110.4 | Z27: 107.4 | AA27: 111.2 | AB27: 106.9 | AC27: 109.4 | AD27: 113.2
A28: Rural+Urban | B28: 2013 | C28: September | D28: 116.4 | E28: 116.9 | F28: 112.3 | G28: 110.5 | H28: 105.3 | I28: 107.3 | J28: 160.9 | K28: 107.1 | L28: 103.1 | M28: 108.3 | N28: 110.7 | O28: 114.6 | P28: 118.3 | Q28: 112 | R28: 112.2 | S28: 110.4 | T28: 111.9 | U28: 109.7 | V28: 110.5 | W28: 109.6 | X28: 108.1 | Y28: 109.9 | Z28: 107.5 | AA28: 110.6 | AB28: 106.8 | AC28: 109 | AD28: 113.7
A29: Rural | B29: 2013 | C29: October | D29: 116.3 | E29: 115.4 | F29: 112.6 | G29: 111.7 | H29: 107.7 | I29: 113.2 | J29: 164.9 | K29: 108.3 | L29: 103.9 | M29: 108.2 | N29: 111.1 | O29: 114.9 | P29: 119.8 | Q29: 112.2 | R29: 113.6 | S29: 112.3 | T29: 113.4 | U29: NA | V29: 111.6 | W29: 110.4 | X29: 108.9 | Y29: 109.3 | Z29: 108.3 | AA29: 110.2 | AB29: 107.5 | AC29: 109.1 | AD29: 115.5
A30: Urban | B30: 2013 | C30: October | D30: 118.9 | E30: 118.1 | F30: 114.5 | G30: 110.4 | H30: 102.3 | I30: 106.2 | J30: 183.5 | K30: 105.3 | L30: 100.2 | M30: 109.6 | N30: 111.4 | O30: 116 | P30: 120.8 | Q30: 113.5 | R30: 112.5 | S30: 109.7 | T30: 112 | U30: 110.5 | V30: 109.7 | W30: 110.2 | X30: 108.2 | Y30: 109.7 | Z30: 108 | AA30: 111.3 | AB30: 107.3 | AC30: 109.4 | AD30: 114
A31: Rural+Urban | B31: 2013 | C31: October | D31: 117.1 | E31: 116.3 | F31: 113.3 | G31: 111.2 | H31: 105.7 | I31: 109.9 | J31: 171.2 | K31: 107.3 | L31: 102.7 | M31: 108.7 | N31: 111.2 | O31: 115.4 | P31: 120.2 | Q31: 112.5 | R31: 113.2 | S31: 111.2 | T31: 112.8 | U31: 110.5 | V31: 110.9 | W31: 110.3 | X31: 108.6 | Y31: 109.5 | Z31: 108.1 | AA31: 110.8 | AB31: 107.4 | AC31: 109.2 | AD31: 114.8
A32: Rural | B32: 2013 | C32: November | D32: 117.3 | E32: 114.9 | F32: 116.2 | G32: 112.8 | H32: 108.9 | I32: 116.6 | J32: 178.1 | K32: 109.1 | L32: 103.6 | M32: 109 | N32: 111.8 | O32: 116 | P32: 122.5 | Q32: 112.8 | R32: 114.6 | S32: 113.1 | T32: 114.4 | U32: NA | V32: 112.6 | W32: 111.3 | X32: 109.7 | Y32: 109.6 | Z32: 108.7 | AA32: 111 | AB32: 108.2 | AC32: 109.8 | AD32: 117.4
A33: Urban | B33: 2013 | C33: November | D33: 119.8 | E33: 116.3 | F33: 122.6 | G33: 112 | H33: 103.2 | I33: 110 | J33: 192.8 | K33: 106.3 | L33: 99.5 | M33: 110.3 | N33: 111.8 | O33: 117.1 | P33: 122.9 | Q33: 114.1 | R33: 113.5 | S33: 110.3 | T33: 113 | U33: 111.1 | V33: 110 | W33: 110.9 | X33: 108.6 | Y33: 109.5 | Z33: 108.5 | AA33: 111.3 | AB33: 107.9 | AC33: 109.6 | AD33: 115
A34: Rural+Urban | B34: 2013 | C34: November | D34: 118.1 | E34: 115.4 | F34: 118.7 | G34: 112.5 | H34: 106.8 | I34: 113.5 | J34: 183.1 | K34: 108.2 | L34: 102.2 | M34: 109.4 | N34: 111.8 | O34: 116.5 | P34: 122.6 | Q34: 113.1 | R34: 114.2 | S34: 111.9 | T34: 113.8 | U34: 111.1 | V34: 111.6 | W34: 111.1 | X34: 109.3 | Y34: 109.5 | Z34: 108.6 | AA34: 111.2 | AB34: 108.1 | AC34: 109.7 | AD34: 116.3
A35: Rural | B35: 2013 | C35: December | D35: 118.4 | E35: 115.9 | F35: 120.4 | G35: 113.8 | H35: 109.5 | I35: 115.5 | J35: 145.7 | K35: 109.5 | L35: 102.9 | M35: 109.8 | N35: 112.1 | O35: 116.8 | P35: 118.7 | Q35: 113.6 | R35: 115.8 | S35: 114 | T35: 115.5 | U35: NA | V35: 112.8 | W35: 112.1 | X35: 110.1 | Y35: 109.9 | Z35: 109.2 | AA35: 111.6 | AB35: 108.1 | AC35: 110.1 | AD35: 115.5
A36: Urban | B36: 2013 | C36: December | D36: 120.5 | E36: 118.1 | F36: 128.5 | G36: 112.8 | H36: 103.4 | I36: 110.7 | J36: 144.8 | K36: 107.1 | L36: 98.6 | M36: 111.9 | N36: 112.1 | O36: 118.1 | P36: 117.8 | Q36: 115 | R36: 114.2 | S36: 110.9 | T36: 113.7 | U36: 110.7 | V36: 110.4 | W36: 111.3 | X36: 109 | Y36: 109.7 | Z36: 108.9 | AA36: 111.4 | AB36: 107.7 | AC36: 109.8 | AD36: 113.3
A37: Rural+Urban | B37: 2013 | C37: December | D37: 119.1 | E37: 116.7 | F37: 123.5 | G37: 113.4 | H37: 107.3 | I37: 113.3 | J37: 145.4 | K37: 108.7 | L37: 101.5 | M37: 110.5 | N37: 112.1 | O37: 117.4 | P37: 118.4 | Q37: 114 | R37: 115.2 | S37: 112.7 | T37: 114.8 | U37: 110.7 | V37: 111.9 | W37: 111.7 | X37: 109.7 | Y37: 109.8 | Z37: 109 | AA37: 111.5 | AB37: 107.9 | AC37: 110 | AD37: 114.5
A38: Rural | B38: 2014 | C38: January | D38: 118.9 | E38: 117.1 | F38: 120.5 | G38: 114.4 | H38: 109 | I38: 115.5 | J38: 123.9 | K38: 109.6 | L38: 101.8 | M38: 110.2 | N38: 112.4 | O38: 117.3 | P38: 116 | Q38: 114 | R38: 116.5 | S38: 114.5 | T38: 116.2 | U38: NA | V38: 113 | W38: 112.6 | X38: 110.6 | Y38: 110.5 | Z38: 109.6 | AA38: 111.8 | AB38: 108.3 | AC38: 110.6 | AD38: 114.2
A39: Urban | B39: 2014 | C39: January | D39: 121.2 | E39: 122 | F39: 129.9 | G39: 113.6 | H39: 102.9 | I39: 112.1 | J39: 118.9 | K39: 107.5 | L39: 96.9 | M39: 112.7 | N39: 112.1 | O39: 119 | P39: 115.5 | Q39: 115.7 | R39: 114.8 | S39: 111.3 | T39: 114.3 | U39: 111.6 | V39: 111 | W39: 111.9 | X39: 109.7 | Y39: 110.8 | Z39: 109.8 | AA39: 111.5 | AB39: 108 | AC39: 110.5 | AD39: 112.9
A40: Rural+Urban | B40: 2014 | C40: January | D40: 119.6 | E40: 118.8 | F40: 124.1 | G40: 114.1 | H40: 106.8 | I40: 113.9 | J40: 122.2 | K40: 108.9 | L40: 100.2 | M40: 111 | N40: 112.3 | O40: 118.1 | P40: 115.8 | Q40: 114.5 | R40: 115.8 | S40: 113.2 | T40: 115.4 | U40: 111.6 | V40: 112.2 | W40: 112.3 | X40: 110.3 | Y40: 110.7 | Z40: 109.7 | AA40: 111.6 | AB40: 108.2 | AC40: 110.6 | AD40: 113.6
...

Sheet CPI_Basket
A1: Q1 — CPI Basket Contribution by Broader Category (May 2023, Rural+Urban)
A4: Broader Category | B4: Avg Index | C4: Contribution % | D4: Sub categories
A5: Food | B5: =AVERAGE( AVERAGEIFS(Raw_Data!D:D,Raw_Data!A:A,"Rural+Urban",Raw_Data!B:B,2023,Raw_Data!C:C,"May"), AVERAGEIFS(Raw_Data!E:E,Raw_Data!A:A,"Rural+Urban",Raw_Data!B:B,2023,Raw_Data!C:C,"May"), AVERAGEIFS(Raw_Data!F:F,Raw_Data!A:A,"Rural+Urban",Raw_Data!B:B,2023,Raw_Data!C:C,"May"), AVERAGEIFS(Raw_Data!G:G,Raw_Data!A:A,"Rural+Urban",Raw_Data!B:B,2023,Raw_Data!C:C,"May"), AVERAGEIFS(Raw_Data!H:H,Raw_Data!A:A,"Rural+Urban",Raw_Data!B:B,2023,Raw_Data!C:C,"May"), AVERAGEIFS(Raw_Data!I:I,Raw_Data!A:A,"Rural+Urban",Raw_Data!B:B,2023,Raw_Data!C:C,"May"), AVERAGEIFS(Raw_Data!J:J,Raw_Data!A:A,"Rural+Urban",Raw_Data!B:B,2023,Raw_Data!C:C,"May"), AVERAGEIFS(Raw_Data!K:K,Raw_Data!A:A,"Rural+Urban",Raw_Data!B:B,2023,Raw_Data!C:C,"May"), AVERAGEIFS(Raw_Data!L:L,Raw_Data!A:A,"Rural+Urban",Raw_Data!B:B,2023,Raw_Data!C:C,"May"), AVERAGEIFS(Raw_Data!M:M,Raw_Data!A:A,"Rural+Urban",Raw_Data!B:B,2023,Raw_Data!C:C,"May"), AVERAGEIFS(Raw_Data!N:N,Raw_Data!A:A,"Rural+Urban",Raw_Data!B:B,2023,Raw_Data!C:C,"May"), AVERAGEIFS(Raw_Data!O:O,Raw_Data!A:A,"Rural+Urban",Raw_Data!B:B,2023,Raw_Data!C:C,"May"), AVERAGEIFS(Raw_Data!P:P,Raw_Data!A:A,"Rural+Urban",Raw_Data!B:B,2023,Raw_Data!C:C,"May") ) -> 177.45385 | C5: =B5/SUM($B$5:$B$16) -> 0.082301106 | D5: Cereals and products, Meat and fish, Egg, Milk and products, Oils and fats, Fruits, Vegetables, Pulses and products, Sugar and Confectionery, Spices, Non-alcoholic beverages, Prepared meals, snacks, sweets etc., Food and beverages
A6: Clothing & Footwear | B6: =AVERAGE( AVERAGEIFS(Raw_Data!R:R,Raw_Data!A:A,"Rural+Urban",Raw_Data!B:B,2023,Raw_Data!C:C,"May"), AVERAGEIFS(Raw_Data!S:S,Raw_Data!A:A,"Rural+Urban",Raw_Data!B:B,2023,Raw_Data!C:C,"May"), AVERAGEIFS(Raw_Data!T:T,Raw_Data!A:A,"Rural+Urban",Raw_Data!B:B,2023,Raw_Data!C:C,"May") ) -> 184.4 | C6: =B6/SUM($B$5:$B$16) -> 0.085522654 | D6: Clothing, Footwear, Clothing and footwear
A7: Housing | B7: =AVERAGEIFS(Raw_Data!U:U,Raw_Data!A:A,"Rural+Urban",Raw_Data!B:B,2023,Raw_Data!C:C,"May") -> 175.6 | C7: =B7/SUM($B$5:$B$16) -> 0.081441313 | D7: Housing
A8: Energy | B8: =AVERAGEIFS(Raw_Data!V:V,Raw_Data!A:A,"Rural+Urban",Raw_Data!B:B,2023,Raw_Data!C:C,"May") -> 182.8 | C8: =B8/SUM($B$5:$B$16) -> 0.084780592 | D8: Fuel and light
A9: Healthcare | B9: =AVERAGEIFS(Raw_Data!X:X,Raw_Data!A:A,"Rural+Urban",Raw_Data!B:B,2023,Raw_Data!C:C,"May") -> 185.7 | C9: =B9/SUM($B$5:$B$16) -> 0.08612558 | D9: Health
A10: Transport & Communication | B10: =AVERAGEIFS(Raw_Data!Y:Y,Raw_Data!A:A,"Rural+Urban",Raw_Data!B:B,2023,Raw_Data!C:C,"May") -> 164.8 | C10: =B10/SUM($B$5:$B$16) -> 0.076432394 | D10: Transport and communication
A11: Education | B11: =AVERAGEIFS(Raw_Data!AA:AA,Raw_Data!A:A,"Rural+Urban",Raw_Data!B:B,2023,Raw_Data!C:C,"May") -> 177.1 | C11: =B11/SUM($B$5:$B$16) -> 0.082136996 | D11: Education
A12: Recreation | B12: =AVERAGEIFS(Raw_Data!Z:Z,Raw_Data!A:A,"Rural+Urban",Raw_Data!B:B,2023,Raw_Data!C:C,"May") -> 171.2 | C12: =B12/SUM($B$5:$B$16) -> 0.079400642 | D12: Recreation and amusement
A13: Personal Care | B13: =AVERAGEIFS(Raw_Data!AB:AB,Raw_Data!A:A,"Rural+Urban",Raw_Data!B:B,2023,Raw_Data!C:C,"May") -> 185.2 | C13: =B13/SUM($B$5:$B$16) -> 0.085893685 | D13: Personal care and effects
A14: Household Goods | B14: =AVERAGEIFS(Raw_Data!W:W,Raw_Data!A:A,"Rural+Urban",Raw_Data!B:B,2023,Raw_Data!C:C,"May") -> 175.2 | C14: =B14/SUM($B$5:$B$16) -> 0.081255797 | D14: Household goods and services
A15: Tobacco & Intoxicants | B15: =AVERAGEIFS(Raw_Data!Q:Q,Raw_Data!A:A,"Rural+Urban",Raw_Data!B:B,2023,Raw_Data!C:C,"May") -> 201 | C15: =B15/SUM($B$5:$B$16) -> 0.093221548 | D15: Pan, tobacco and intoxicants
A16: Miscellaneous | B16: =AVERAGEIFS(Raw_Data!AC:AC,Raw_Data!A:A,"Rural+Urban",Raw_Data!B:B,2023,Raw_Data!C:C,"May") -> 175.7 | C16: =B16/SUM($B$5:$B$16) -> 0.081487692 | D16: Miscellaneous
A17: TOTAL | C17: =SUM(C5:C16) -> 1
A23: Q1 insights Tobacco & Intoxicants has the highest contribution (~9.3%) because its index value has risen the most since the base year — meaning prices in this category have inflated the most overall. Food comes in around 8.2% despite being the largest spending category — this is because equal weights are assumed across all categories per the problem statement. All 12 bucket contributions sum to exactly 100%

Sheet YOY_Inflation 
A1: Q2 — Year-on-Year CPI Inflation Rate (Rural+Urban, General Index), 2017–2023
A3: Year | B3: Jan CPI (Start) | C3: Dec/Last CPI (End) | D3: YoY Rate | E3: Key Driver
A4: 2017 | B4: =AVERAGEIFS(Raw_Data!AD:AD,Raw_Data!A:A,"Rural+Urban",Raw_Data!B:B,A4,Raw_Data!C:C,"January") -> 130.3 | C4: =AVERAGEIFS(Raw_Data!AD:AD,Raw_Data!A:A,"Rural+Urban",Raw_Data!B:B,A4,Raw_Data!C:C,"December") -> 137.2 | D4: =(C4-B4)/B4 -> 0.05295472 | E4: Post-demonetisation recovery; food prices normalizing
A5: 2018 | B5: =AVERAGEIFS(Raw_Data!AD:AD,Raw_Data!A:A,"Rural+Urban",Raw_Data!B:B,A5,Raw_Data!C:C,"January") -> 136.9 | C5: =AVERAGEIFS(Raw_Data!AD:AD,Raw_Data!A:A,"Rural+Urban",Raw_Data!B:B,A5,Raw_Data!C:C,"December") -> 140.1 | D5: =(C5-B5)/B5 -> 0.023374726 | E5: Low food inflation; stable global commodity prices
A6: 2019 | B6: =AVERAGEIFS(Raw_Data!AD:AD,Raw_Data!A:A,"Rural+Urban",Raw_Data!B:B,A6,Raw_Data!C:C,"January") -> 139.6 | C6: =AVERAGEIFS(Raw_Data!AD:AD,Raw_Data!A:A,"Rural+Urban",Raw_Data!B:B,A6,Raw_Data!C:C,"December") -> 150.4 | D6: =(C6-B6)/B6 -> 0.077363897 | E6: Onion price surge 300%+; crop failure due to unseasonal rains
A7: 2020 | B7: =AVERAGEIFS(Raw_Data!AD:AD,Raw_Data!A:A,"Rural+Urban",Raw_Data!B:B,A7,Raw_Data!C:C,"January") -> 150.2 | C7: =AVERAGEIFS(Raw_Data!AD:AD,Raw_Data!A:A,"Rural+Urban",Raw_Data!B:B,A7,Raw_Data!C:C,"December") -> 158.9 | D7: =(C7-B7)/B7 -> 0.05792277 | E7: COVID lockdown supply disruptions; food price spike
A8: 2021 | B8: =AVERAGEIFS(Raw_Data!AD:AD,Raw_Data!A:A,"Rural+Urban",Raw_Data!B:B,A8,Raw_Data!C:C,"January") -> 157.3 | C8: =AVERAGEIFS(Raw_Data!AD:AD,Raw_Data!A:A,"Rural+Urban",Raw_Data!B:B,A8,Raw_Data!C:C,"December") -> 166.2 | D8: =(C8-B8)/B8 -> 0.056579784 | E8: Post-lockdown demand rebound; global supply chain stress
A9: 2022 | B9: =AVERAGEIFS(Raw_Data!AD:AD,Raw_Data!A:A,"Rural+Urban",Raw_Data!B:B,A9,Raw_Data!C:C,"January") -> 165.7 | C9: =AVERAGEIFS(Raw_Data!AD:AD,Raw_Data!A:A,"Rural+Urban",Raw_Data!B:B,A9,Raw_Data!C:C,"December") -> 175.7 | D9: =(C9-B9)/B9 -> 0.06035003 | E9: Russia-Ukraine war; global energy & food commodity spike
A10: 2023 | B10: =AVERAGEIFS(Raw_Data!AD:AD,Raw_Data!A:A,"Rural+Urban",Raw_Data!B:B,A10,Raw_Data!C:C,"January") -> 176.5 | C10: =AVERAGEIFS(Raw_Data!AD:AD,Raw_Data!A:A,"Rural+Urban",Raw_Data!B:B,2023,Raw_Data!C:C,"May") -> 179.1 | D10: =(C10-B10)/B10 -> 0.014730878 | E10: Partial data (Jan–May); food prices easing; base effects
A14: Q2 Insights
A15: 2019 had the highest inflation at ~7.74%. India faced its worst onion shortage in decades — unseasonal rains destroyed crops, onion prices surged 300%+, pushing food and overall CPI to a peak for the entire 2017–2023 period.

Sheet Food_Inflation
A1: Q3 — Food Inflation Analysis: 12 Months Ending May 2023 (Rural+Urban)
A3: Part A — Month-on-Month Food Index & Inflation
A4: Period | B4: Food Avg Index | C4: MoM Change | D4: MoM % Change | E4: Highlight
A5: 2022 June | B5: {=AVERAGE(_xlfn._xlws.FILTER(Raw_Data!D:O,(Raw_Data!A:A="Rural+Urban")*(Raw_Data!B:B=2022)*(Raw_Data!C:C="June")))} -> 173.91667
A6: 2022 July | B6: {=AVERAGE(_xlfn._xlws.FILTER(Raw_Data!D:O,(Raw_Data!A:A="Rural+Urban")*(Raw_Data!B:B=2022)*(Raw_Data!C:C="July")))} -> 174.275 | C6: =B6-B5 -> 0.35833333 | D6: =(B6-B5)/B5 -> 0.0020603737
A7: 2022 August | B7: {=AVERAGE(_xlfn._xlws.FILTER(Raw_Data!D:O,(Raw_Data!A:A="Rural+Urban")*(Raw_Data!B:B=2022)*(Raw_Data!C:C="August")))} -> 174.40833 | C7: =B7-B6 -> 0.13333333 | D7: =(B7-B6)/B6 -> 0.00076507436
A8: 2022 September | B8: {=AVERAGE(_xlfn._xlws.FILTER(Raw_Data!D:O,(Raw_Data!A:A="Rural+Urban")*(Raw_Data!B:B=2022)*(Raw_Data!C:C="September")))} -> 175.25833 | C8: =B8-B7 -> 0.85 | D8: =(B8-B7)/B7 -> 0.0048736203
A9: 2022 October | B9: {=AVERAGE(_xlfn._xlws.FILTER(Raw_Data!D:O,(Raw_Data!A:A="Rural+Urban")*(Raw_Data!B:B=2022)*(Raw_Data!C:C="October")))} -> 176.475 | C9: =B9-B8 -> 1.2166667 | D9: =(B9-B8)/B8 -> 0.006942133
A10: 2022 November | B10: {=AVERAGE(_xlfn._xlws.FILTER(Raw_Data!D:O,(Raw_Data!A:A="Rural+Urban")*(Raw_Data!B:B=2022)*(Raw_Data!C:C="November")))} -> 176.54167 | C10: =B10-B9 -> 0.066666667 | D10: =(B10-B9)/B9 -> 0.00037776833
A11: 2022 December | B11: {=AVERAGE(_xlfn._xlws.FILTER(Raw_Data!D:O,(Raw_Data!A:A="Rural+Urban")*(Raw_Data!B:B=2022)*(Raw_Data!C:C="December")))} -> 175.625 | C11: =B11-B10 -> -0.91666667 | D11: =(B11-B10)/B10 -> -0.0051923531
A12: 2023 January | B12: {=AVERAGE(_xlfn._xlws.FILTER(Raw_Data!D:O,(Raw_Data!A:A="Rural+Urban")*(Raw_Data!B:B=2023)*(Raw_Data!C:C="January")))} -> 176.33333 | C12: =B12-B11 -> 0.70833333 | D12: =(B12-B11)/B11 -> 0.0040332147
A13: 2023 February | B13: {=AVERAGE(_xlfn._xlws.FILTER(Raw_Data!D:O,(Raw_Data!A:A="Rural+Urban")*(Raw_Data!B:B=2023)*(Raw_Data!C:C="February")))} -> 175.175 | C13: =B13-B12 -> -1.1583333 | D13: =(B13-B12)/B12 -> -0.0065689981 | E13: Lowest Inflation
A14: 2023 March | B14: {=AVERAGE(_xlfn._xlws.FILTER(Raw_Data!D:O,(Raw_Data!A:A="Rural+Urban")*(Raw_Data!B:B=2023)*(Raw_Data!C:C="March")))} -> 175.18333 | C14: =B14-B13 -> 0.0083333333 | D14: =(B14-B13)/B13 -> 4.7571476e-05
A15: 2023 April | B15: {=AVERAGE(_xlfn._xlws.FILTER(Raw_Data!D:O,(Raw_Data!A:A="Rural+Urban")*(Raw_Data!B:B=2023)*(Raw_Data!C:C="April")))} -> 175.975 | C15: =B15-B14 -> 0.79166667 | D15: =(B15-B14)/B14 -> 0.0045190753
A16: 2023 May | B16: {=AVERAGE(_xlfn._xlws.FILTER(Raw_Data!D:O,(Raw_Data!A:A="Rural+Urban")*(Raw_Data!B:B=2023)*(Raw_Data!C:C="May")))} -> 177.31667 | C16: =B16-B15 -> 1.3416667 | D16: =(B16-B15)/B15 -> 0.007624189 | E16: Highest Inflation
A19: Part B — Absolute Change in Individual Food Categories (Jun 2022 → May 2023)
A20: Food Sub-Category | B20: Jun 2022 Index | C20: May 2023 Index | D20: Absolute Change | E20: Direction
A21: Spices | B21: =AVERAGEIFS(Raw_Data!M:M,Raw_Data!A:A,"Rural+Urban",Raw_Data!B:B,2022,Raw_Data!C:C,"June") -> 187.1 | C21: =AVERAGEIFS(Raw_Data!M:M,Raw_Data!A:A,"Rural+Urban",Raw_Data!B:B,2023,Raw_Data!C:C,"May") -> 218 | D21: =C21-B21 -> 30.9 | E21: ▲ Inflation
A22: Cereals and products | B22: =AVERAGEIFS(Raw_Data!D:D,Raw_Data!A:A,"Rural+Urban",Raw_Data!B:B,2022,Raw_Data!C:C,"June") -> 155 | C22: =AVERAGEIFS(Raw_Data!D:D,Raw_Data!A:A,"Rural+Urban",Raw_Data!B:B,2023,Raw_Data!C:C,"May") -> 173.7 | D22: =C22-B22 -> 18.7 | E22: ▲ Inflation
A23: Milk and products | B23: =AVERAGEIFS(Raw_Data!G:G,Raw_Data!A:A,"Rural+Urban",Raw_Data!B:B,2022,Raw_Data!C:C,"June") -> 165.8 | C23: =AVERAGEIFS(Raw_Data!G:G,Raw_Data!A:A,"Rural+Urban",Raw_Data!B:B,2023,Raw_Data!C:C,"May") -> 179.5 | D23: =C23-B23 -> 13.7 | E23: ▲ Inflation
A24: Pulses and products | B24: =AVERAGEIFS(Raw_Data!K:K,Raw_Data!A:A,"Rural+Urban",Raw_Data!B:B,2022,Raw_Data!C:C,"June") -> 164.3 | C24: =AVERAGEIFS(Raw_Data!K:K,Raw_Data!A:A,"Rural+Urban",Raw_Data!B:B,2023,Raw_Data!C:C,"May") -> 175.6 | D24: =C24-B24 -> 11.3 | E24: ▲ Inflation
A25: Prepared meals, snacks, sweets etc. | B25: =AVERAGEIFS(Raw_Data!O:O,Raw_Data!A:A,"Rural+Urban",Raw_Data!B:B,2022,Raw_Data!C:C,"June") -> 183.9 | C25: =AVERAGEIFS(Raw_Data!O:O,Raw_Data!A:A,"Rural+Urban",Raw_Data!B:B,2023,Raw_Data!C:C,"May") -> 194.2 | D25: =C25-B25 -> 10.3 | E25: ▲ Inflation
A26: Non-alcoholic beverages | B26: =AVERAGEIFS(Raw_Data!N:N,Raw_Data!A:A,"Rural+Urban",Raw_Data!B:B,2022,Raw_Data!C:C,"June") -> 167.9 | C26: =AVERAGEIFS(Raw_Data!N:N,Raw_Data!A:A,"Rural+Urban",Raw_Data!B:B,2023,Raw_Data!C:C,"May") -> 173.4 | D26: =C26-B26 -> 5.5 | E26: ▲ Inflation
A27: Sugar and Confectionery | B27: =AVERAGEIFS(Raw_Data!L:L,Raw_Data!A:A,"Rural+Urban",Raw_Data!B:B,2022,Raw_Data!C:C,"June") -> 119.9 | C27: =AVERAGEIFS(Raw_Data!L:L,Raw_Data!A:A,"Rural+Urban",Raw_Data!B:B,2023,Raw_Data!C:C,"May") -> 122.7 | D27: =C27-B27 -> 2.8 | E27: ▲ Inflation
A28: Fruits | B28: =AVERAGEIFS(Raw_Data!I:I,Raw_Data!A:A,"Rural+Urban",Raw_Data!B:B,2022,Raw_Data!C:C,"June") -> 169.7 | C28: =AVERAGEIFS(Raw_Data!I:I,Raw_Data!A:A,"Rural+Urban",Raw_Data!B:B,2023,Raw_Data!C:C,"May") -> 172.2 | D28: =C28-B28 -> 2.5 | E28: ▲ Inflation
A29: Egg | B29: =AVERAGEIFS(Raw_Data!F:F,Raw_Data!A:A,"Rural+Urban",Raw_Data!B:B,2022,Raw_Data!C:C,"June") -> 170.8 | C29: =AVERAGEIFS(Raw_Data!F:F,Raw_Data!A:A,"Rural+Urban",Raw_Data!B:B,2023,Raw_Data!C:C,"May") -> 173.2 | D29: =C29-B29 -> 2.4 | E29: ▲ Inflation
A30: Meat and fish | B30: =AVERAGEIFS(Raw_Data!E:E,Raw_Data!A:A,"Rural+Urban",Raw_Data!B:B,2022,Raw_Data!C:C,"June") -> 219.4 | C30: =AVERAGEIFS(Raw_Data!E:E,Raw_Data!A:A,"Rural+Urban",Raw_Data!B:B,2023,Raw_Data!C:C,"May") -> 214.3 | D30: =C30-B30 -> -5.1 | E30: ▼ Deflation
A31: Vegetables | B31: =AVERAGEIFS(Raw_Data!J:J,Raw_Data!A:A,"Rural+Urban",Raw_Data!B:B,2022,Raw_Data!C:C,"June") -> 182.3 | C31: =AVERAGEIFS(Raw_Data!J:J,Raw_Data!A:A,"Rural+Urban",Raw_Data!B:B,2023,Raw_Data!C:C,"May") -> 161 | D31: =C31-B31 -> -21.3 | E31: ▼ Deflation
A32: Oils and fats | B32: =AVERAGEIFS(Raw_Data!H:H,Raw_Data!A:A,"Rural+Urban",Raw_Data!B:B,2022,Raw_Data!C:C,"June") -> 200.9 | C32: =AVERAGEIFS(Raw_Data!H:H,Raw_Data!A:A,"Rural+Urban",Raw_Data!B:B,2023,Raw_Data!C:C,"May") -> 170 | D32: =C32-B32 -> -30.9 | E32: ▼ Deflation
A35: Q3 Insights
A37: Highest food inflation month: October 2022 (+0.72% MoM) — festive season demand (Navratri, Diwali) pushed vegetables and spices prices up sharply.
A39: Lowest food inflation month: February 2023 (−0.59% MoM) — post-harvest season flooded markets with fresh supply, cooling prices.
A41: Biggest inflationary sub-category: Spices (+30.9 index points) — erratic monsoon and global supply disruptions drove sustained price increases.
A43: Biggest deflationary sub-category: Oils & Fats (−30.9 points) — global edible oil prices crashed after the 2022 Ukraine war commodity spike cooled. India imports ~60% of edible oils so benefited directly.

Sheet COVID_Impact
A1: Q4 — COVID-19 Impact on CPI Inflation (Rural+Urban, 2019–2021)
A3: Period | B3: Year | C3: General Index | D3: MoM% General | E3: Health Index | F3: Health MoM% | G3: Food & Bev Index | H3: Food Mom% | I3: Fuel & Light | J3: Fuel MoM%
A4: 2019 January | B4: 2019 | C4: =AVERAGEIFS( Clean_Data!AD:AD, Clean_Data!A:A,"Rural+Urban", Clean_Data!B:B,B4, Clean_Data!C:C,TEXT(DATEVALUE("1-"&RIGHT(A4,LEN(A4)-FIND(" ",A4))&"-"&B4),"mmmm") ) -> 139.6 | E4: =AVERAGEIFS( Clean_Data!X:X, Clean_Data!A:A,"Rural+Urban", Clean_Data!B:B,B4, Clean_Data!C:C,TEXT(DATEVALUE("1-"&RIGHT(A4,LEN(A4)-FIND(" ",A4))&"-"&B4),"mmmm") ) -> 145.1 | G4: =AVERAGEIFS( Clean_Data!P:P, Clean_Data!A:A,"Rural+Urban", Clean_Data!B:B,B4, Clean_Data!C:C,TEXT(DATEVALUE("1-"&RIGHT(A4,LEN(A4)-FIND(" ",A4))&"-"&B4),"mmmm") ) -> 137.4 | I4: =AVERAGEIFS( Clean_Data!V:V, Clean_Data!A:A,"Rural+Urban", Clean_Data!B:B,B4, Clean_Data!C:C,TEXT(DATEVALUE("1-"&RIGHT(A4,LEN(A4)-FIND(" ",A4))&"-"&B4),"mmmm") ) -> 139.5
A5: 2019 February | B5: 2019 | C5: =AVERAGEIFS( Clean_Data!AD:AD, Clean_Data!A:A,"Rural+Urban", Clean_Data!B:B,B5, Clean_Data!C:C,TEXT(DATEVALUE("1-"&RIGHT(A5,LEN(A5)-FIND(" ",A5))&"-"&B5),"mmmm") ) -> 139.9 | D5: =(C5-C4)/C4 -> 0.0021489971 | E5: =AVERAGEIFS( Clean_Data!X:X, Clean_Data!A:A,"Rural+Urban", Clean_Data!B:B,B5, Clean_Data!C:C,TEXT(DATEVALUE("1-"&RIGHT(A5,LEN(A5)-FIND(" ",A5))&"-"&B5),"mmmm") ) -> 145.6 | F5: =(E5-E4)/E4 -> 0.0034458994 | G5: =AVERAGEIFS( Clean_Data!P:P, Clean_Data!A:A,"Rural+Urban", Clean_Data!B:B,B5, Clean_Data!C:C,TEXT(DATEVALUE("1-"&RIGHT(A5,LEN(A5)-FIND(" ",A5))&"-"&B5),"mmmm") ) -> 137.5 | H5: =(G5-G4)/G4 -> 0.00072780204 | I5: =AVERAGEIFS( Clean_Data!V:V, Clean_Data!A:A,"Rural+Urban", Clean_Data!B:B,B5, Clean_Data!C:C,TEXT(DATEVALUE("1-"&RIGHT(A5,LEN(A5)-FIND(" ",A5))&"-"&B5),"mmmm") ) -> 138.4 | J5: =(I5-I4)/I4 -> -0.0078853047
A6: 2019 March | B6: 2019 | C6: =AVERAGEIFS( Clean_Data!AD:AD, Clean_Data!A:A,"Rural+Urban", Clean_Data!B:B,B6, Clean_Data!C:C,TEXT(DATEVALUE("1-"&RIGHT(A6,LEN(A6)-FIND(" ",A6))&"-"&B6),"mmmm") ) -> 140.4 | D6: =(C6-C5)/C5 -> 0.0035739814 | E6: =AVERAGEIFS( Clean_Data!X:X, Clean_Data!A:A,"Rural+Urban", Clean_Data!B:B,B6, Clean_Data!C:C,TEXT(DATEVALUE("1-"&RIGHT(A6,LEN(A6)-FIND(" ",A6))&"-"&B6),"mmmm") ) -> 146.2 | F6: =(E6-E5)/E5 -> 0.0041208791 | G6: =AVERAGEIFS( Clean_Data!P:P, Clean_Data!A:A,"Rural+Urban", Clean_Data!B:B,B6, Clean_Data!C:C,TEXT(DATEVALUE("1-"&RIGHT(A6,LEN(A6)-FIND(" ",A6))&"-"&B6),"mmmm") ) -> 138.1 | H6: =(G6-G5)/G5 -> 0.0043636364 | I6: =AVERAGEIFS( Clean_Data!V:V, Clean_Data!A:A,"Rural+Urban", Clean_Data!B:B,B6, Clean_Data!C:C,TEXT(DATEVALUE("1-"&RIGHT(A6,LEN(A6)-FIND(" ",A6))&"-"&B6),"mmmm") ) -> 139.7 | J6: =(I6-I5)/I5 -> 0.0093930636
A7: 2019 May | B7: 2019 | C7: =AVERAGEIFS( Clean_Data!AD:AD, Clean_Data!A:A,"Rural+Urban", Clean_Data!B:B,B7, Clean_Data!C:C,TEXT(DATEVALUE("1-"&RIGHT(A7,LEN(A7)-FIND(" ",A7))&"-"&B7),"mmmm") ) -> 142 | D7: =(C7-C6)/C6 -> 0.011396011 | E7: =AVERAGEIFS( Clean_Data!X:X, Clean_Data!A:A,"Rural+Urban", Clean_Data!B:B,B7, Clean_Data!C:C,TEXT(DATEVALUE("1-"&RIGHT(A7,LEN(A7)-FIND(" ",A7))&"-"&B7),"mmmm") ) -> 146.9 | F7: =(E7-E6)/E6 -> 0.0047879617 | G7: =AVERAGEIFS( Clean_Data!P:P, Clean_Data!A:A,"Rural+Urban", Clean_Data!B:B,B7, Clean_Data!C:C,TEXT(DATEVALUE("1-"&RIGHT(A7,LEN(A7)-FIND(" ",A7))&"-"&B7),"mmmm") ) -> 140.9 | H7: =(G7-G6)/G6 -> 0.020275163 | I7: =AVERAGEIFS( Clean_Data!V:V, Clean_Data!A:A,"Rural+Urban", Clean_Data!B:B,B7, Clean_Data!C:C,TEXT(DATEVALUE("1-"&RIGHT(A7,LEN(A7)-FIND(" ",A7))&"-"&B7),"mmmm") ) -> 140.3 | J7: =(I7-I6)/I6 -> 0.0042949177
A8: 2019 June | B8: 2019 | C8: =AVERAGEIFS( Clean_Data!AD:AD, Clean_Data!A:A,"Rural+Urban", Clean_Data!B:B,B8, Clean_Data!C:C,TEXT(DATEVALUE("1-"&RIGHT(A8,LEN(A8)-FIND(" ",A8))&"-"&B8),"mmmm") ) -> 142.9 | D8: =(C8-C7)/C7 -> 0.0063380282 | E8: =AVERAGEIFS( Clean_Data!X:X, Clean_Data!A:A,"Rural+Urban", Clean_Data!B:B,B8, Clean_Data!C:C,TEXT(DATEVALUE("1-"&RIGHT(A8,LEN(A8)-FIND(" ",A8))&"-"&B8),"mmmm") ) -> 147.4 | F8: =(E8-E7)/E7 -> 0.003403676 | G8: =AVERAGEIFS( Clean_Data!P:P, Clean_Data!A:A,"Rural+Urban", Clean_Data!B:B,B8, Clean_Data!C:C,TEXT(DATEVALUE("1-"&RIGHT(A8,LEN(A8)-FIND(" ",A8))&"-"&B8),"mmmm") ) -> 142.7 | H8: =(G8-G7)/G7 -> 0.012775018 | I8: =AVERAGEIFS( Clean_Data!V:V, Clean_Data!A:A,"Rural+Urban", Clean_Data!B:B,B8, Clean_Data!C:C,TEXT(DATEVALUE("1-"&RIGHT(A8,LEN(A8)-FIND(" ",A8))&"-"&B8),"mmmm") ) -> 141.2 | J8: =(I8-I7)/I7 -> 0.0064148254
A9: 2019 July | B9: 2019 | C9: =AVERAGEIFS( Clean_Data!AD:AD, Clean_Data!A:A,"Rural+Urban", Clean_Data!B:B,B9, Clean_Data!C:C,TEXT(DATEVALUE("1-"&RIGHT(A9,LEN(A9)-FIND(" ",A9))&"-"&B9),"mmmm") ) -> 144.2 | D9: =(C9-C8)/C8 -> 0.0090972708 | E9: =AVERAGEIFS( Clean_Data!X:X, Clean_Data!A:A,"Rural+Urban", Clean_Data!B:B,B9, Clean_Data!C:C,TEXT(DATEVALUE("1-"&RIGHT(A9,LEN(A9)-FIND(" ",A9))&"-"&B9),"mmmm") ) -> 147.9 | F9: =(E9-E8)/E8 -> 0.0033921303 | G9: =AVERAGEIFS( Clean_Data!P:P, Clean_Data!A:A,"Rural+Urban", Clean_Data!B:B,B9, Clean_Data!C:C,TEXT(DATEVALUE("1-"&RIGHT(A9,LEN(A9)-FIND(" ",A9))&"-"&B9),"mmmm") ) -> 144.7 | H9: =(G9-G8)/G8 -> 0.014015417 | I9: =AVERAGEIFS( Clean_Data!V:V, Clean_Data!A:A,"Rural+Urban", Clean_Data!B:B,B9, Clean_Data!C:C,TEXT(DATEVALUE("1-"&RIGHT(A9,LEN(A9)-FIND(" ",A9))&"-"&B9),"mmmm") ) -> 139.3 | J9: =(I9-I8)/I8 -> -0.013456091
A10: 2019 August | B10: 2019 | C10: =AVERAGEIFS( Clean_Data!AD:AD, Clean_Data!A:A,"Rural+Urban", Clean_Data!B:B,B10, Clean_Data!C:C,TEXT(DATEVALUE("1-"&RIGHT(A10,LEN(A10)-FIND(" ",A10))&"-"&B10),"mmmm") ) -> 145 | D10: =(C10-C9)/C9 -> 0.0055478502 | E10: =AVERAGEIFS( Clean_Data!X:X, Clean_Data!A:A,"Rural+Urban", Clean_Data!B:B,B10, Clean_Data!C:C,TEXT(DATEVALUE("1-"&RIGHT(A10,LEN(A10)-FIND(" ",A10))&"-"&B10),"mmmm") ) -> 148.5 | F10: =(E10-E9)/E9 -> 0.0040567951 | G10: =AVERAGEIFS( Clean_Data!P:P, Clean_Data!A:A,"Rural+Urban", Clean_Data!B:B,B10, Clean_Data!C:C,TEXT(DATEVALUE("1-"&RIGHT(A10,LEN(A10)-FIND(" ",A10))&"-"&B10),"mmmm") ) -> 145.9 | H10: =(G10-G9)/G9 -> 0.00829302 | I10: =AVERAGEIFS( Clean_Data!V:V, Clean_Data!A:A,"Rural+Urban", Clean_Data!B:B,B10, Clean_Data!C:C,TEXT(DATEVALUE("1-"&RIGHT(A10,LEN(A10)-FIND(" ",A10))&"-"&B10),"mmmm") ) -> 138.5 | J10: =(I10-I9)/I9 -> -0.0057430007
A11: 2019 September | B11: 2019 | C11: =AVERAGEIFS( Clean_Data!AD:AD, Clean_Data!A:A,"Rural+Urban", Clean_Data!B:B,B11, Clean_Data!C:C,TEXT(DATEVALUE("1-"&RIGHT(A11,LEN(A11)-FIND(" ",A11))&"-"&B11),"mmmm") ) -> 145.8 | D11: =(C11-C10)/C10 -> 0.0055172414 | E11: =AVERAGEIFS( Clean_Data!X:X, Clean_Data!A:A,"Rural+Urban", Clean_Data!B:B,B11, Clean_Data!C:C,TEXT(DATEVALUE("1-"&RIGHT(A11,LEN(A11)-FIND(" ",A11))&"-"&B11),"mmmm") ) -> 149 | F11: =(E11-E10)/E10 -> 0.0033670034 | G11: =AVERAGEIFS( Clean_Data!P:P, Clean_Data!A:A,"Rural+Urban", Clean_Data!B:B,B11, Clean_Data!C:C,TEXT(DATEVALUE("1-"&RIGHT(A11,LEN(A11)-FIND(" ",A11))&"-"&B11),"mmmm") ) -> 147 | H11: =(G11-G10)/G10 -> 0.0075394106 | I11: =AVERAGEIFS( Clean_Data!V:V, Clean_Data!A:A,"Rural+Urban", Clean_Data!B:B,B11, Clean_Data!C:C,TEXT(DATEVALUE("1-"&RIGHT(A11,LEN(A11)-FIND(" ",A11))&"-"&B11),"mmmm") ) -> 139.2 | J11: =(I11-I10)/I10 -> 0.0050541516
A12: 2019 October | B12: 2019 | C12: =AVERAGEIFS( Clean_Data!AD:AD, Clean_Data!A:A,"Rural+Urban", Clean_Data!B:B,B12, Clean_Data!C:C,TEXT(DATEVALUE("1-"&RIGHT(A12,LEN(A12)-FIND(" ",A12))&"-"&B12),"mmmm") ) -> 147.2 | D12: =(C12-C11)/C11 -> 0.0096021948 | E12: =AVERAGEIFS( Clean_Data!X:X, Clean_Data!A:A,"Rural+Urban", Clean_Data!B:B,B12, Clean_Data!C:C,TEXT(DATEVALUE("1-"&RIGHT(A12,LEN(A12)-FIND(" ",A12))&"-"&B12),"mmmm") ) -> 149.4 | F12: =(E12-E11)/E11 -> 0.0026845638 | G12: =AVERAGEIFS( Clean_Data!P:P, Clean_Data!A:A,"Rural+Urban", Clean_Data!B:B,B12, Clean_Data!C:C,TEXT(DATEVALUE("1-"&RIGHT(A12,LEN(A12)-FIND(" ",A12))&"-"&B12),"mmmm") ) -> 149.6 | H12: =(G12-G11)/G11 -> 0.017687075 | I12: =AVERAGEIFS( Clean_Data!V:V, Clean_Data!A:A,"Rural+Urban", Clean_Data!B:B,B12, Clean_Data!C:C,TEXT(DATEVALUE("1-"&RIGHT(A12,LEN(A12)-FIND(" ",A12))&"-"&B12),"mmmm") ) -> 140.6 | J12: =(I12-I11)/I11 -> 0.010057471
A13: 2019 November | B13: 2019 | C13: =AVERAGEIFS( Clean_Data!AD:AD, Clean_Data!A:A,"Rural+Urban", Clean_Data!B:B,B13, Clean_Data!C:C,TEXT(DATEVALUE("1-"&RIGHT(A13,LEN(A13)-FIND(" ",A13))&"-"&B13),"mmmm") ) -> 148.6 | D13: =(C13-C12)/C12 -> 0.0095108696 | E13: =AVERAGEIFS( Clean_Data!X:X, Clean_Data!A:A,"Rural+Urban", Clean_Data!B:B,B13, Clean_Data!C:C,TEXT(DATEVALUE("1-"&RIGHT(A13,LEN(A13)-FIND(" ",A13))&"-"&B13),"mmmm") ) -> 149.9 | F13: =(E13-E12)/E12 -> 0.0033467202 | G13: =AVERAGEIFS( Clean_Data!P:P, Clean_Data!A:A,"Rural+Urban", Clean_Data!B:B,B13, Clean_Data!C:C,TEXT(DATEVALUE("1-"&RIGHT(A13,LEN(A13)-FIND(" ",A13))&"-"&B13),"mmmm") ) -> 151.9 | H13: =(G13-G12)/G12 -> 0.015374332 | I13: =AVERAGEIFS( Clean_Data!V:V, Clean_Data!A:A,"Rural+Urban", Clean_Data!B:B,B13, Clean_Data!C:C,TEXT(DATEVALUE("1-"&RIGHT(A13,LEN(A13)-FIND(" ",A13))&"-"&B13),"mmmm") ) -> 142.3 | J13: =(I13-I12)/I12 -> 0.012091038
A14: 2019 December | B14: 2019 | C14: =AVERAGEIFS( Clean_Data!AD:AD, Clean_Data!A:A,"Rural+Urban", Clean_Data!B:B,B14, Clean_Data!C:C,TEXT(DATEVALUE("1-"&RIGHT(A14,LEN(A14)-FIND(" ",A14))&"-"&B14),"mmmm") ) -> 150.4 | D14: =(C14-C13)/C13 -> 0.012113055 | E14: =AVERAGEIFS( Clean_Data!X:X, Clean_Data!A:A,"Rural+Urban", Clean_Data!B:B,B14, Clean_Data!C:C,TEXT(DATEVALUE("1-"&RIGHT(A14,LEN(A14)-FIND(" ",A14))&"-"&B14),"mmmm") ) -> 150.4 | F14: =(E14-E13)/E13 -> 0.003335557 | G14: =AVERAGEIFS( Clean_Data!P:P, Clean_Data!A:A,"Rural+Urban", Clean_Data!B:B,B14, Clean_Data!C:C,TEXT(DATEVALUE("1-"&RIGHT(A14,LEN(A14)-FIND(" ",A14))&"-"&B14),"mmmm") ) -> 155 | H14: =(G14-G13)/G13 -> 0.020408163 | I14: =AVERAGEIFS( Clean_Data!V:V, Clean_Data!A:A,"Rural+Urban", Clean_Data!B:B,B14, Clean_Data!C:C,TEXT(DATEVALUE("1-"&RIGHT(A14,LEN(A14)-FIND(" ",A14))&"-"&B14),"mmmm") ) -> 143.7 | J14: =(I14-I13)/I13 -> 0.0098383696
A15: 2020 January | B15: 2020 | C15: =AVERAGEIFS( Clean_Data!AD:AD, Clean_Data!A:A,"Rural+Urban", Clean_Data!B:B,B15, Clean_Data!C:C,TEXT(DATEVALUE("1-"&RIGHT(A15,LEN(A15)-FIND(" ",A15))&"-"&B15),"mmmm") ) -> 150.2 | D15: =(C15-C14)/C14 -> -0.0013297872 | E15: =AVERAGEIFS( Clean_Data!X:X, Clean_Data!A:A,"Rural+Urban", Clean_Data!B:B,B15, Clean_Data!C:C,TEXT(DATEVALUE("1-"&RIGHT(A15,LEN(A15)-FIND(" ",A15))&"-"&B15),"mmmm") ) -> 151.2 | F15: =(E15-E14)/E14 -> 0.0053191489 | G15: =AVERAGEIFS( Clean_Data!P:P, Clean_Data!A:A,"Rural+Urban", Clean_Data!B:B,B15, Clean_Data!C:C,TEXT(DATEVALUE("1-"&RIGHT(A15,LEN(A15)-FIND(" ",A15))&"-"&B15),"mmmm") ) -> 153.5 | H15: =(G15-G14)/G14 -> -0.0096774194 | I15: =AVERAGEIFS( Clean_Data!V:V, Clean_Data!A:A,"Rural+Urban", Clean_Data!B:B,B15, Clean_Data!C:C,TEXT(DATEVALUE("1-"&RIGHT(A15,LEN(A15)-FIND(" ",A15))&"-"&B15),"mmmm") ) -> 144.6 | J15: =(I15-I14)/I14 -> 0.006263048
A16: 2020 February | B16: 2020 | C16: =AVERAGEIFS( Clean_Data!AD:AD, Clean_Data!A:A,"Rural+Urban", Clean_Data!B:B,B16, Clean_Data!C:C,TEXT(DATEVALUE("1-"&RIGHT(A16,LEN(A16)-FIND(" ",A16))&"-"&B16),"mmmm") ) -> 149.1 | D16: =(C16-C15)/C15 -> -0.0073235686 | E16: =AVERAGEIFS( Clean_Data!X:X, Clean_Data!A:A,"Rural+Urban", Clean_Data!B:B,B16, Clean_Data!C:C,TEXT(DATEVALUE("1-"&RIGHT(A16,LEN(A16)-FIND(" ",A16))&"-"&B16),"mmmm") ) -> 151.7 | F16: =(E16-E15)/E15 -> 0.0033068783 | G16: =AVERAGEIFS( Clean_Data!P:P, Clean_Data!A:A,"Rural+Urban", Clean_Data!B:B,B16, Clean_Data!C:C,TEXT(DATEVALUE("1-"&RIGHT(A16,LEN(A16)-FIND(" ",A16))&"-"&B16),"mmmm") ) -> 150.5 | H16: =(G16-G15)/G15 -> -0.019543974 | I16: =AVERAGEIFS( Clean_Data!V:V, Clean_Data!A:A,"Rural+Urban", Clean_Data!B:B,B16, Clean_Data!C:C,TEXT(DATEVALUE("1-"&RIGHT(A16,LEN(A16)-FIND(" ",A16))&"-"&B16),"mmmm") ) -> 147.2 | J16: =(I16-I15)/I15 -> 0.017980636
... A38: 2021 December | B38: 2021 | C38: =AVERAGEIFS( Clean_Data!AD:AD, Clean_Data!A:A,"Rural+Urban", Clean_Data!B:B,B38, Clean_Data!C:C,TEXT(DATEVALUE("1-"&RIGHT(A38,LEN(A38)-FIND(" ",A38))&"-"&B38),"mmmm") ) -> 166.2 | D38: =(C38-C37)/C37 -> -0.0029994001 | E38: =AVERAGEIFS( Clean_Data!X:X, Clean_Data!A:A,"Rural+Urban", Clean_Data!B:B,B38, Clean_Data!C:C,TEXT(DATEVALUE("1-"&RIGHT(A38,LEN(A38)-FIND(" ",A38))&"-"&B38),"mmmm") ) -> 170.6 | F38: =(E38-E37)/E37 -> 0.0041200706 | G38: =AVERAGEIFS( Clean_Data!P:P, Clean_Data!A:A,"Rural+Urban", Clean_Data!B:B,B38, Clean_Data!C:C,TEXT(DATEVALUE("1-"&RIGHT(A38,LEN(A38)-FIND(" ",A38))&"-"&B38),"mmmm") ) -> 168.2 | H38: =(G38-G37)/G37 -> -0.0088391279 | I38: =AVERAGEIFS( Clean_Data!V:V, Clean_Data!A:A,"Rural+Urban", Clean_Data!B:B,B38, Clean_Data!C:C,TEXT(DATEVALUE("1-"&RIGHT(A38,LEN(A38)-FIND(" ",A38))&"-"&B38),"mmmm") ) -> 164.1 | J38: =(I38-I37)/I37 -> 0.0012202563
A41: Pre Vs Post Summary Table
A43: Period | B43: Avg General Index | C43: Avg Health | D43: Avg Food | E43: Avg Fuel
A44: Pre-COVID (Jan 2019 – Feb 2020) | B44: =AVERAGE(C4:C16) -> 145.02308 | C44: =AVERAGE(E4:E16) -> 148.4 | D44: =AVERAGE(G4:G16) -> 145.74615 | E44: =AVERAGE(I4:I16) -> 141.11538
A45: Post-COVID (Mar 2020 – Dec 2021) | B45: =AVERAGE(C17:C38) -> 158.32727 | C45: =AVERAGE(E17:E38) -> 161.12727 | D45: =AVERAGE(G17:G38) -> 159.81364 | E45: =AVERAGE(I17:I38) -> 153.17273
A49: Q4 Insights :
A51: Overall inflation rose +9.4% — Pre-COVID avg General Index ~145.0 vs Post-COVID ~158.6. The pandemic clearly pushed prices up across all categories.
A53: Healthcare accelerated the most post-March 2020 — demand for medicines, hospital services, PPE and oxygen surged. Health CPI stayed elevated consistently through all of 2020 and 2021.
A55: Food showed a paradox — prices briefly fell during the strictest lockdown months as demand collapsed and supply couldn't move. Then rebounded sharply in late 2020 as supply chains reopened unevenly under pent-up demand.
